[2022-08-09 13:23:11,813 INFO root] Taurus CLI Tool v1.15.4
[2022-08-09 13:23:11,813 DEBUG root] Build: 14133 Fri Jul  9 09:34:42 UTC 2021
[2022-08-09 13:23:11,813 DEBUG root] Extended git info:  7267e07e Release 1.15.4
[2022-08-09 13:23:11,813 DEBUG root] Command-line options: {'log': '/tmp/artifacts/bzt.log', 'option': None, 'quiet': None, 'verbose': None, 'no_system_configs': None, 'aliases': ['cloud']}
[2022-08-09 13:23:11,813 DEBUG root] Python: CPython 3.8.10
[2022-08-09 13:23:11,813 DEBUG root] OS: uname_result(system='Linux', node='513c6ebc1bb1', release='5.10.47-linuxkit', version='#1 SMP Sat Jul 3 21:51:47 UTC 2021', machine='x86_64', processor='x86_64')
[2022-08-09 13:23:11,814 DEBUG root] Path to interpreter: /usr/bin/python3
[2022-08-09 13:23:11,814 DEBUG root] Path to packages: ['/usr/local/bin', '/usr/lib/python38.zip', '/usr/lib/python3.8', '/usr/lib/python3.8/lib-dynload', '/usr/local/lib/python3.8/dist-packages', '/usr/lib/python3/dist-packages']
[2022-08-09 13:23:11,815 DEBUG root] Default python: None
[2022-08-09 13:23:11,815 DEBUG root] Default python3: /usr/bin/python3
[2022-08-09 13:23:11,816 DEBUG root] Using personal config: /root/.bzt-rc
[2022-08-09 13:23:11,816 INFO root] Starting with configs: ['demo-taurus-elliegrid.yml', '/root/.bzt-rc']
[2022-08-09 13:23:11,816 INFO Engine] Configuring...
[2022-08-09 13:23:11,817 DEBUG Engine] Reading system configs from: /etc/bzt.d
[2022-08-09 13:23:11,865 DEBUG Engine] Base configs list: ['/usr/local/lib/python3.8/dist-packages/bzt/resources/10-base-config.yml', '/etc/bzt.d/90-artifacts-dir.json', '/etc/bzt.d/99-zinstallID.json']
[2022-08-09 13:23:11,866 DEBUG Engine.Configuration] Configs: ['/usr/local/lib/python3.8/dist-packages/bzt/resources/10-base-config.yml', '/etc/bzt.d/90-artifacts-dir.json', '/etc/bzt.d/99-zinstallID.json']
[2022-08-09 13:23:11,866 DEBUG Engine.Configuration] Reading /usr/local/lib/python3.8/dist-packages/bzt/resources/10-base-config.yml as YAML
[2022-08-09 13:23:11,897 DEBUG Engine.Configuration] Reading /etc/bzt.d/90-artifacts-dir.json as YAML
[2022-08-09 13:23:11,898 DEBUG Engine.Configuration] Reading /etc/bzt.d/99-zinstallID.json as YAML
[2022-08-09 13:23:11,898 DEBUG Engine] User configs list: ['demo-taurus-elliegrid.yml', '/root/.bzt-rc']
[2022-08-09 13:23:11,898 DEBUG Engine.Configuration] Configs: ['demo-taurus-elliegrid.yml', '/root/.bzt-rc']
[2022-08-09 13:23:11,913 DEBUG Engine.Configuration] Reading demo-taurus-elliegrid.yml as YAML
[2022-08-09 13:23:11,922 DEBUG Engine.Configuration] Reading /root/.bzt-rc as YAML
[2022-08-09 13:23:11,926 DEBUG Engine.Configuration] Configs: ['demo-taurus-elliegrid.yml', '/root/.bzt-rc']
[2022-08-09 13:23:11,928 DEBUG Engine.Configuration] Reading demo-taurus-elliegrid.yml as YAML
[2022-08-09 13:23:11,934 DEBUG Engine.Configuration] Reading /root/.bzt-rc as YAML
[2022-08-09 13:23:11,951 DEBUG Engine] Requesting updates info: https://gettaurus.org/updates/?version=1.15.4&installID=Docker
[2022-08-09 13:23:11,951 DEBUG HTTPClient] Making HTTP request GET https://gettaurus.org/updates/?version=1.15.4&installID=Docker
[2022-08-09 13:23:11,952 INFO Engine] Artifacts dir: /bzt-configs/build/132311
[2022-08-09 13:23:11,964 DEBUG urllib3.connectionpool] Starting new HTTPS connection (1): gettaurus.org:443
[2022-08-09 13:23:11,985 DEBUG Engine] New artifact filename: /bzt-configs/build/132311/effective
[2022-08-09 13:23:11,996 DEBUG Engine.Configuration] Dumping YAML config into /bzt-configs/build/132311/effective.yml
[2022-08-09 13:23:12,043 DEBUG Engine.Configuration] Dumping JSON config into /bzt-configs/build/132311/effective.json
[2022-08-09 13:23:12,050 DEBUG Engine] New artifact filename: /bzt-configs/build/132311/merged.yml
[2022-08-09 13:23:12,054 DEBUG Engine.Configuration] Dumping YAML config into /bzt-configs/build/132311/merged.yml
[2022-08-09 13:23:12,060 DEBUG Engine] New artifact filename: /bzt-configs/build/132311/merged.json
[2022-08-09 13:23:12,064 DEBUG Engine.Configuration] Dumping JSON config into /bzt-configs/build/132311/merged.json
[2022-08-09 13:23:12,065 DEBUG Engine] Add existing artifact (move=False): demo-taurus-elliegrid.yml
[2022-08-09 13:23:12,066 DEBUG Engine] Copying demo-taurus-elliegrid.yml to /bzt-configs/build/132311/demo-taurus-elliegrid.yml
[2022-08-09 13:23:12,082 DEBUG Engine] Add existing artifact (move=False): /root/.bzt-rc
[2022-08-09 13:23:12,082 DEBUG Engine] Copying /root/.bzt-rc to /bzt-configs/build/132311/.bzt-rc
[2022-08-09 13:23:12,097 DEBUG Engine] Set PYTHONPATH to :
	USER: '/root/.bzt/python-packages/3.8.10' +
	TEMP: '/bzt-configs/build/132311/python-packages/3.8.10' +
	CURRENT: ''
[2022-08-09 13:23:12,097 DEBUG Engine] Content of user packages dir: []
[2022-08-09 13:23:12,098 DEBUG Engine] OS env: OBJC_DISABLE_INITIALIZE_FORK_SAFETY=YES
[2022-08-09 13:23:12,098 DEBUG Engine] OS env: LOCAL_THREAD_COUNT=1
[2022-08-09 13:23:12,098 DEBUG Engine] OS env: CLOUD_THREAD_COUNT=1
[2022-08-09 13:23:12,098 DEBUG Engine] OS env: RAMP_UP=5
[2022-08-09 13:23:12,098 DEBUG Engine] OS env: HOLD_FOR=22
[2022-08-09 13:23:12,098 DEBUG Engine] OS env: THINK-TIME=2000ms
[2022-08-09 13:23:12,098 DEBUG Engine] OS env: TIME-OUT=50s
[2022-08-09 13:23:12,098 DEBUG Engine] OS env: TAURUS_ARTIFACTS_DIR=/bzt-configs/build/132311
[2022-08-09 13:23:12,099 DEBUG root] Closing log handler: /tmp/artifacts/bzt.log
[2022-08-09 13:23:12,120 DEBUG root] Switched writing logs to /bzt-configs/build/132311/bzt.log
[2022-08-09 13:23:12,121 DEBUG root] Linting config
[2022-08-09 13:23:12,124 WARNING root] at path 'execution.0.scenario': scenario 'elliegrid_pills' is used but isn't defined
[2022-08-09 13:23:12,127 INFO Engine] Preparing...
[2022-08-09 13:23:12,129 DEBUG Engine] Module config: consolidator {'class': 'bzt.modules.aggregator.ConsolidatingAggregator'}
[2022-08-09 13:23:12,130 DEBUG root] Importing module: bzt.modules.aggregator
[2022-08-09 13:23:12,917 DEBUG HTTPClient] Request resulted in exception: Traceback (most recent call last):
  File "/usr/lib/python3/dist-packages/urllib3/contrib/pyopenssl.py", line 485, in wrap_socket
    cnx.do_handshake()
  File "/usr/local/lib/python3.8/dist-packages/OpenSSL/SSL.py", line 1828, in do_handshake
    self._raise_ssl_error(self._ssl, result)
  File "/usr/local/lib/python3.8/dist-packages/OpenSSL/SSL.py", line 1566, in _raise_ssl_error
    _raise_current_error()
  File "/usr/local/lib/python3.8/dist-packages/OpenSSL/_util.py", line 57, in exception_from_error_queue
    raise exception_type(errors)
OpenSSL.SSL.Error: [('SSL routines', 'tls_process_server_certificate', 'certificate verify failed')]

During handling of the above exception, another exception occurred:

Traceback (most recent call last):
  File "/usr/lib/python3/dist-packages/urllib3/connectionpool.py", line 665, in urlopen
    httplib_response = self._make_request(
  File "/usr/lib/python3/dist-packages/urllib3/connectionpool.py", line 376, in _make_request
    self._validate_conn(conn)
  File "/usr/lib/python3/dist-packages/urllib3/connectionpool.py", line 996, in _validate_conn
    conn.connect()
  File "/usr/lib/python3/dist-packages/urllib3/connection.py", line 366, in connect
    self.sock = ssl_wrap_socket(
  File "/usr/lib/python3/dist-packages/urllib3/util/ssl_.py", line 370, in ssl_wrap_socket
    return context.wrap_socket(sock, server_hostname=server_hostname)
  File "/usr/lib/python3/dist-packages/urllib3/contrib/pyopenssl.py", line 491, in wrap_socket
    raise ssl.SSLError("bad handshake: %r" % e)
ssl.SSLError: ("bad handshake: Error([('SSL routines', 'tls_process_server_certificate', 'certificate verify failed')])",)

During handling of the above exception, another exception occurred:

Traceback (most recent call last):
  File "/usr/lib/python3/dist-packages/requests/adapters.py", line 439, in send
    resp = conn.urlopen(
  File "/usr/lib/python3/dist-packages/urllib3/connectionpool.py", line 719, in urlopen
    retries = retries.increment(
  File "/usr/lib/python3/dist-packages/urllib3/util/retry.py", line 436, in increment
    raise MaxRetryError(_pool, url, error or ResponseError(cause))
urllib3.exceptions.MaxRetryError: HTTPSConnectionPool(host='gettaurus.org', port=443): Max retries exceeded with url: /updates/?version=1.15.4&installID=Docker (Caused by SSLError(SSLError("bad handshake: Error([('SSL routines', 'tls_process_server_certificate', 'certificate verify failed')])")))

During handling of the above exception, another exception occurred:

Traceback (most recent call last):
  File "/usr/local/lib/python3.8/dist-packages/bzt/utils.py", line 1243, in request
    return self.session.request(method, url, *args, **kwargs)
  File "/usr/lib/python3/dist-packages/requests/sessions.py", line 533, in request
    resp = self.send(prep, **send_kwargs)
  File "/usr/lib/python3/dist-packages/requests/sessions.py", line 646, in send
    r = adapter.send(request, **kwargs)
  File "/usr/lib/python3/dist-packages/requests/adapters.py", line 514, in send
    raise SSLError(e, request=request)
requests.exceptions.SSLError: HTTPSConnectionPool(host='gettaurus.org', port=443): Max retries exceeded with url: /updates/?version=1.15.4&installID=Docker (Caused by SSLError(SSLError("bad handshake: Error([('SSL routines', 'tls_process_server_certificate', 'certificate verify failed')])")))

[2022-08-09 13:23:12,922 DEBUG Engine] Failed to check for updates: Traceback (most recent call last):
  File "/usr/lib/python3/dist-packages/urllib3/contrib/pyopenssl.py", line 485, in wrap_socket
    cnx.do_handshake()
  File "/usr/local/lib/python3.8/dist-packages/OpenSSL/SSL.py", line 1828, in do_handshake
    self._raise_ssl_error(self._ssl, result)
  File "/usr/local/lib/python3.8/dist-packages/OpenSSL/SSL.py", line 1566, in _raise_ssl_error
    _raise_current_error()
  File "/usr/local/lib/python3.8/dist-packages/OpenSSL/_util.py", line 57, in exception_from_error_queue
    raise exception_type(errors)
OpenSSL.SSL.Error: [('SSL routines', 'tls_process_server_certificate', 'certificate verify failed')]

During handling of the above exception, another exception occurred:

Traceback (most recent call last):
  File "/usr/lib/python3/dist-packages/urllib3/connectionpool.py", line 665, in urlopen
    httplib_response = self._make_request(
  File "/usr/lib/python3/dist-packages/urllib3/connectionpool.py", line 376, in _make_request
    self._validate_conn(conn)
  File "/usr/lib/python3/dist-packages/urllib3/connectionpool.py", line 996, in _validate_conn
    conn.connect()
  File "/usr/lib/python3/dist-packages/urllib3/connection.py", line 366, in connect
    self.sock = ssl_wrap_socket(
  File "/usr/lib/python3/dist-packages/urllib3/util/ssl_.py", line 370, in ssl_wrap_socket
    return context.wrap_socket(sock, server_hostname=server_hostname)
  File "/usr/lib/python3/dist-packages/urllib3/contrib/pyopenssl.py", line 491, in wrap_socket
    raise ssl.SSLError("bad handshake: %r" % e)
ssl.SSLError: ("bad handshake: Error([('SSL routines', 'tls_process_server_certificate', 'certificate verify failed')])",)

During handling of the above exception, another exception occurred:

Traceback (most recent call last):
  File "/usr/lib/python3/dist-packages/requests/adapters.py", line 439, in send
    resp = conn.urlopen(
  File "/usr/lib/python3/dist-packages/urllib3/connectionpool.py", line 719, in urlopen
    retries = retries.increment(
  File "/usr/lib/python3/dist-packages/urllib3/util/retry.py", line 436, in increment
    raise MaxRetryError(_pool, url, error or ResponseError(cause))
urllib3.exceptions.MaxRetryError: HTTPSConnectionPool(host='gettaurus.org', port=443): Max retries exceeded with url: /updates/?version=1.15.4&installID=Docker (Caused by SSLError(SSLError("bad handshake: Error([('SSL routines', 'tls_process_server_certificate', 'certificate verify failed')])")))

During handling of the above exception, another exception occurred:

Traceback (most recent call last):
  File "/usr/local/lib/python3.8/dist-packages/bzt/utils.py", line 1243, in request
    return self.session.request(method, url, *args, **kwargs)
  File "/usr/lib/python3/dist-packages/requests/sessions.py", line 533, in request
    resp = self.send(prep, **send_kwargs)
  File "/usr/lib/python3/dist-packages/requests/sessions.py", line 646, in send
    r = adapter.send(request, **kwargs)
  File "/usr/lib/python3/dist-packages/requests/adapters.py", line 514, in send
    raise SSLError(e, request=request)
requests.exceptions.SSLError: HTTPSConnectionPool(host='gettaurus.org', port=443): Max retries exceeded with url: /updates/?version=1.15.4&installID=Docker (Caused by SSLError(SSLError("bad handshake: Error([('SSL routines', 'tls_process_server_certificate', 'certificate verify failed')])")))

During handling of the above exception, another exception occurred:

Traceback (most recent call last):
  File "/usr/local/lib/python3.8/dist-packages/bzt/engine/engine.py", line 728, in _check_updates
    response = client.request('GET', addr, timeout=10)
  File "/usr/local/lib/python3.8/dist-packages/bzt/utils.py", line 1250, in request
    raise TaurusNetworkError(msg)
bzt.TaurusNetworkError: Request to https://gettaurus.org/updates/?version=1.15.4&installID=Docker failed

[2022-08-09 13:23:12,925 WARNING Engine] Failed to check for updates
[2022-08-09 13:23:13,518 DEBUG root] Loading class: 'ConsolidatingAggregator' from <module 'bzt.modules.aggregator' from '/usr/local/lib/python3.8/dist-packages/bzt/modules/aggregator.py'>
[2022-08-09 13:23:13,520 DEBUG Engine.consolidator] Buffer scaling setup: percentile 95.0 from [0.0, 50.0, 90.0, 95.0, 99.0, 99.9, 100.0] selected
[2022-08-09 13:23:13,521 DEBUG Engine] Module config: monitoring {'class': 'bzt.modules.monitoring.Monitoring'}
[2022-08-09 13:23:13,522 DEBUG root] Importing module: bzt.modules.monitoring
[2022-08-09 13:23:13,537 DEBUG root] Loading class: 'Monitoring' from <module 'bzt.modules.monitoring' from '/usr/local/lib/python3.8/dist-packages/bzt/modules/monitoring.py'>
[2022-08-09 13:23:13,538 DEBUG Engine] Module config: cloud {'class': 'bzt.modules.blazemeter.CloudProvisioning', 'default-location': 'us-central1-a', 'token': '********', 'account': 943147, 'workspace': 960443, 'project': 1092205, 'report-name': 'Elliegrid', 'test': 'Assessment flow', 'browser-open': 'none', 'public-report': True, 'send-report-email': False, 'upload-artifacts': False}
[2022-08-09 13:23:13,539 DEBUG root] Importing module: bzt.modules.blazemeter
[2022-08-09 13:23:13,578 DEBUG easyprocess] version=0.3
[2022-08-09 13:23:13,582 DEBUG pyvirtualdisplay] version=2.2
[2022-08-09 13:23:13,585 DEBUG root] Loading class: 'CloudProvisioning' from <module 'bzt.modules.blazemeter' from '/usr/local/lib/python3.8/dist-packages/bzt/modules/blazemeter/__init__.py'>
[2022-08-09 13:23:13,586 DEBUG Engine] Module config: blazemeter {'class': 'bzt.modules.blazemeter.BlazeMeterUploader', 'dedicated-ips': False}
[2022-08-09 13:23:13,587 DEBUG root] Importing module: bzt.modules.blazemeter
[2022-08-09 13:23:13,588 DEBUG root] Loading class: 'BlazeMeterUploader' from <module 'bzt.modules.blazemeter' from '/usr/local/lib/python3.8/dist-packages/bzt/modules/blazemeter/__init__.py'>
[2022-08-09 13:23:13,589 DEBUG Engine.cloud] Installing http client
[2022-08-09 13:23:13,590 DEBUG Engine.cloud] Request: GET https://a.blazemeter.com/api/v4/accounts None
[2022-08-09 13:23:13,592 DEBUG HTTPClient] Making HTTP request GET https://a.blazemeter.com/api/v4/accounts
[2022-08-09 13:23:13,594 DEBUG urllib3.connectionpool] Starting new HTTPS connection (1): a.blazemeter.com:443
[2022-08-09 13:23:14,716 DEBUG urllib3.connectionpool] https://a.blazemeter.com:443 "GET /api/v4/accounts HTTP/1.1" 200 1664
[2022-08-09 13:23:14,723 DEBUG Engine.cloud] Response [200]: {
    "limit": 10,
    "skip": 0,
    "total": 1,
    "hidden": 0,
    "api_version": 4,
    "error": null,
    "result": [
        {
            "id": 943147,
            "name": "Default Account",
            "thumbnailUrl": null,
            "salesforce
[2022-08-09 13:23:14,725 DEBUG Engine.cloud] Request: GET https://a.blazemeter.com/api/v4/workspaces?accountId=943147&enabled=true&limit=100 None
[2022-08-09 13:23:14,727 DEBUG HTTPClient] Making HTTP request GET https://a.blazemeter.com/api/v4/workspaces?accountId=943147&enabled=true&limit=100
[2022-08-09 13:23:15,020 DEBUG urllib3.connectionpool] https://a.blazemeter.com:443 "GET /api/v4/workspaces?accountId=943147&enabled=true&limit=100 HTTP/1.1" 200 812
[2022-08-09 13:23:15,026 DEBUG Engine.cloud] Response [200]: {
    "limit": 100,
    "skip": 0,
    "total": 1,
    "hidden": 0,
    "api_version": 4,
    "error": null,
    "result": [
        {
            "id": 960443,
            "name": "Default workspace",
            "userId": 1409497,
            "created": 
[2022-08-09 13:23:15,029 DEBUG Engine] Module config: locust {'class': 'bzt.modules.locustio.LocustIOExecutor'}
[2022-08-09 13:23:15,031 DEBUG root] Importing module: bzt.modules.locustio
[2022-08-09 13:23:15,076 DEBUG root] Loading class: 'LocustIOExecutor' from <module 'bzt.modules.locustio' from '/usr/local/lib/python3.8/dist-packages/bzt/modules/locustio.py'>
[2022-08-09 13:23:15,079 DEBUG Engine.cloud.ProjectFinder] Parsed test link: None
[2022-08-09 13:23:15,081 DEBUG Engine.cloud.ProjectFinder] Treating account name as ID: 943147
[2022-08-09 13:23:15,082 DEBUG Engine.cloud] Request: GET https://a.blazemeter.com/api/v4/accounts None
[2022-08-09 13:23:15,084 DEBUG HTTPClient] Making HTTP request GET https://a.blazemeter.com/api/v4/accounts
[2022-08-09 13:23:15,365 DEBUG urllib3.connectionpool] https://a.blazemeter.com:443 "GET /api/v4/accounts HTTP/1.1" 200 1664
[2022-08-09 13:23:15,370 DEBUG Engine.cloud] Response [200]: {
    "limit": 10,
    "skip": 0,
    "total": 1,
    "hidden": 0,
    "api_version": 4,
    "error": null,
    "result": [
        {
            "id": 943147,
            "name": "Default Account",
            "thumbnailUrl": null,
            "salesforce
[2022-08-09 13:23:15,374 DEBUG Engine.cloud.ProjectFinder] Treating workspace name as ID: 960443
[2022-08-09 13:23:15,376 DEBUG Engine.cloud] Request: GET https://a.blazemeter.com/api/v4/workspaces?accountId=943147&enabled=true&limit=100 None
[2022-08-09 13:23:15,378 DEBUG HTTPClient] Making HTTP request GET https://a.blazemeter.com/api/v4/workspaces?accountId=943147&enabled=true&limit=100
[2022-08-09 13:23:15,644 DEBUG urllib3.connectionpool] https://a.blazemeter.com:443 "GET /api/v4/workspaces?accountId=943147&enabled=true&limit=100 HTTP/1.1" 200 832
[2022-08-09 13:23:15,649 DEBUG Engine.cloud] Response [200]: {
    "limit": 100,
    "skip": 0,
    "total": 1,
    "hidden": 0,
    "api_version": 4,
    "error": null,
    "result": [
        {
            "id": 960443,
            "name": "Default workspace",
            "userId": 1409497,
            "created": 
[2022-08-09 13:23:15,654 DEBUG Engine.cloud.ProjectFinder] Treating project name as ID: 1092205
[2022-08-09 13:23:15,656 DEBUG Engine.cloud] Request: GET https://a.blazemeter.com/api/v4/projects?workspaceId=960443&limit=1000 None
[2022-08-09 13:23:15,658 DEBUG HTTPClient] Making HTTP request GET https://a.blazemeter.com/api/v4/projects?workspaceId=960443&limit=1000
[2022-08-09 13:23:15,931 DEBUG urllib3.connectionpool] https://a.blazemeter.com:443 "GET /api/v4/projects?workspaceId=960443&limit=1000 HTTP/1.1" 200 448
[2022-08-09 13:23:15,936 DEBUG Engine.cloud] Response [200]: {
    "limit": 1000,
    "skip": 0,
    "total": 1,
    "hidden": 0,
    "api_version": 4,
    "error": null,
    "result": [
        {
            "id": 1092205,
            "name": "Default project",
            "userId": null,
            "description":
[2022-08-09 13:23:15,939 DEBUG Engine.cloud] Request: GET https://a.blazemeter.com/api/v4/tests?projectId=1092205&name=Assessment+flow None
[2022-08-09 13:23:15,942 DEBUG HTTPClient] Making HTTP request GET https://a.blazemeter.com/api/v4/tests?projectId=1092205&name=Assessment+flow
[2022-08-09 13:23:16,248 DEBUG urllib3.connectionpool] https://a.blazemeter.com:443 "GET /api/v4/tests?projectId=1092205&name=Assessment+flow HTTP/1.1" 200 1993
[2022-08-09 13:23:16,253 DEBUG Engine.cloud] Response [200]: {
    "limit": 10,
    "skip": 0,
    "total": 1,
    "hidden": 0,
    "api_version": 4,
    "error": null,
    "result": [
        {
            "id": 9888878,
            "name": "Assessment flow",
            "isNewTest": true,
            "userId": 140
[2022-08-09 13:23:16,259 DEBUG Engine.cloud] Request: GET https://a.blazemeter.com/api/v4/workspaces/960443 None
[2022-08-09 13:23:16,261 DEBUG HTTPClient] Making HTTP request GET https://a.blazemeter.com/api/v4/workspaces/960443
[2022-08-09 13:23:16,677 DEBUG urllib3.connectionpool] https://a.blazemeter.com:443 "GET /api/v4/workspaces/960443 HTTP/1.1" 200 None
[2022-08-09 13:23:17,102 DEBUG Engine.cloud] Response [200]: {
    "api_version": 4,
    "error": null,
    "result": {
        "id": 960443,
        "name": "Default workspace",
        "userId": 1409497,
        "created": 1629730320,
        "updated": 1629730320,
        "enabled": true,
        "dedicatedIpsEna
[2022-08-09 13:23:17,118 WARNING Engine] Could not find location at path: elliegrid_pills
[2022-08-09 13:23:17,131 ERROR root] Config Error: Scenario 'elliegrid_pills' not found in scenarios: dict_keys(['chat_assessment'])
[2022-08-09 13:23:17,148 DEBUG root] TaurusConfigError: Scenario 'elliegrid_pills' not found in scenarios: dict_keys(['chat_assessment'])
  File "/usr/local/lib/python3.8/dist-packages/bzt/cli.py", line 274, in perform
    self.engine.prepare()
  File "/usr/local/lib/python3.8/dist-packages/bzt/engine/engine.py", line 220, in prepare
    self.__prepare_provisioning()
  File "/usr/local/lib/python3.8/dist-packages/bzt/engine/engine.py", line 631, in __prepare_provisioning
    self.provisioning.prepare()
  File "/usr/local/lib/python3.8/dist-packages/bzt/modules/blazemeter/cloud_provisioning.py", line 268, in prepare
    res_files = self.get_rfiles()
  File "/usr/local/lib/python3.8/dist-packages/bzt/modules/blazemeter/cloud_provisioning.py", line 116, in get_rfiles
    executor_rfiles = executor.get_resource_files()
  File "/usr/local/lib/python3.8/dist-packages/bzt/engine/modules.py", line 415, in get_resource_files
    files_list.extend(self.resource_files())
  File "/usr/local/lib/python3.8/dist-packages/bzt/modules/locustio.py", line 142, in resource_files
    script = self.get_script_path()
  File "/usr/local/lib/python3.8/dist-packages/bzt/engine/modules.py", line 218, in get_script_path
    scenario = self.get_scenario()
  File "/usr/local/lib/python3.8/dist-packages/bzt/engine/modules.py", line 246, in get_scenario
    scenario_dict = scenarios.get(label, exc)
  File "/usr/local/lib/python3.8/dist-packages/bzt/utils.py", line 324, in get
    raise default
[2022-08-09 13:23:17,150 INFO Engine] Post-processing...
[2022-08-09 13:23:17,152 WARNING Engine.cloud] Part of result data might be missed here due to BM API specifics
[2022-08-09 13:23:17,156 DEBUG Engine.consolidator] Consolidator buffer[0]: dict_keys([])
[2022-08-09 13:23:17,164 DEBUG Engine.Configuration] Dumping YAML config into /bzt-configs/build/132311/effective.yml
[2022-08-09 13:23:17,200 DEBUG Engine.Configuration] Dumping JSON config into /bzt-configs/build/132311/effective.json
[2022-08-09 13:23:17,204 INFO root] Artifacts dir: /bzt-configs/build/132311
[2022-08-09 13:23:17,206 WARNING root] Done performing with code: 1
[2022-08-09 13:23:17,208 DEBUG root] Closing log handler: /bzt-configs/build/132311/bzt.log
